Workbook

Sheet menus
A1: id | B1: name_fr | C1: name_en | D1: price | E1: description_fr | F1: description_en | G1: image_url | H1: featured | I1: category | J1: sort_order | K1: (入力メモ)
A2: 自動採番（空白でOK→Supabaseが付与） | B2: フランス語メニュー名 ※必須 | D2: 価格（数字のみ）例: 38 | E2: フランス語説明文 | F2: 英語説明文 | G2: 画像URL（StorageのPublic URL） | H2: TRUE / FALSE | I2: カテゴリ（リストから選択） | J2: 表示順（数字）例: 1 | K2: ← 自分用メモ欄（CSV出力時は除く）
B3: SUSHI | C3: Sushi | D3: 19 | E3: (8 sushis + 6 makis) Thon, Saumon, Poisson blanc, Maquereau, Seiche, Crevette cuite | F3: (8 sushi + 6 maki rolls) Tuna, Salmon, White Fish, Mackerel, Cuttlefish, Cooked Shrimp | G3: https://umjqopsyrylnvwkranvw.supabase.co/storage/v1/object/public/menu_img/sushi.webp | H3: FALSE | I3: Menu de midi | J3: 1
B4: SUSHI Spécial | C4: Sushi Special | D4: 21 | E4: (9 sushis + 3 makis + 3 makis saumon-avocat) Thon, Saumon, Anguille, Crevette crue, St. Jaques, Hokki, Oeuf de saumon | F4: (9 sushi + 3 maki rolls + 3 salmon & avocado maki rolls) Tuna, Salmon, Eel, Raw Shrimp, Scallop, Surf Clam (Hokkigai), Salmon Roe | G4: https://umjqopsyrylnvwkranvw.supabase.co/storage/v1/object/public/menu_img/sushispecial.webp | H4: FALSE | I4: Menu de midi | J4: 2
B5: SUSHI Saumon | C5: Sushi Salmon | D5: 19 | E5: (8 sushis Saumon cru et mi-cuit + 6 makis saumon) | F5: (8 sushi: raw and lightly seared salmon + 6 salmon maki rolls) | G5: https://umjqopsyrylnvwkranvw.supabase.co/storage/v1/object/public/menu_img/sushisaumon.webp | H5: FALSE | I5: Menu de midi | J5: 3
B6: MAKI | C6: Maki Rolls | D6: 19 | E6: (18 makis Thon, saumon, Saumon-avocat Concombre, Poisson blanc) | F6: (18 maki rolls) Tuna, Salmon, Salmon & Avocado, Cucumber, White Fish | G6: https://umjqopsyrylnvwkranvw.supabase.co/storage/v1/object/public/menu_img/maki.webp | H6: FALSE | I6: Menu de midi | J6: 4
B7: CHIRASHI | C7: Chirashi | D7: 19 | E7: Thon, Saumon, Poisson blanc, Maquereau, Seiche, Crevette cuite | F7: Tuna, Salmon, White Fish, Mackerel, Cuttlefish, Cooked Shrimp | G7: https://umjqopsyrylnvwkranvw.supabase.co/storage/v1/object/public/menu_img/chirashi.webp | H7: FALSE | I7: Menu de midi | J7: 5
B8: CHIRASHI Spécial | C8: Chirashi Special | D8: 22 | E8: Thon, Saumon, Anguille, Crevette crue, St. Jaques, Hokki, Maquereau, Oeuf de saumon | F8: Tuna, Salmon, Eel, Raw Shrimp, Scallop, Surf Clam (Hokkigai), Mackerel, Salmon Roe | G8: https://umjqopsyrylnvwkranvw.supabase.co/storage/v1/object/public/menu_img/chirashisp.webp | H8: FALSE | I8: Menu de midi | J8: 6
B9: CHIRASHI Saumon | C9: Chirashi Salmon | D9: 19 | G9: https://umjqopsyrylnvwkranvw.supabase.co/storage/v1/object/public/menu_img/chirashisaumon.webp | H9: FALSE | I9: Menu de midi | J9: 7
B10: CHIRASHI Saumon Avocat | C10: Chirashi Salmon & Avocado | D10: 20 | G10: https://umjqopsyrylnvwkranvw.supabase.co/storage/v1/object/public/menu_img/chirashisa.webp | H10: FALSE | I10: Menu de midi | J10: 8
B11: BARA CHIRASHI sauce maison | C11: Bara Chirashi (House Special Sauce) | D11: 18 | E11: (Dés de poisson crus à la sauce sucrée sur grand bol de riz) | F11: (Diced raw fish with sweet sauce over a large bowl of rice) | G11: https://umjqopsyrylnvwkranvw.supabase.co/storage/v1/object/public/menu_img/bara.webp | H11: FALSE | I11: Menu de midi | J11: 9
B12: Tartare de SAUMON | C12: Salmon Tartare | D12: 18 | E12: (Saumon haché avec sauce blanche sur grand bol de riz) | F12: (Minced salmon with creamy white sauce over a large bowl of rice) | G12: https://umjqopsyrylnvwkranvw.supabase.co/storage/v1/object/public/menu_img/bara.webp | H12: FALSE | I12: Menu de midi | J12: 10
B13: SASHIMI | C13: Sashimi | D13: 19 | E13: Thon, Saumon, Poisson blanc, Maquereau, Séiche, Crevette cuite | F13: Tuna, Salmon, White Fish, Mackerel, Cuttlefish, Cooked Shrimp | G13: https://umjqopsyrylnvwkranvw.supabase.co/storage/v1/object/public/menu_img/sashimi.webp | H13: FALSE | I13: Menu de midi | J13: 11
B14: SASHIMI Spécial | C14: Sashimi Special | D14: 22 | E14: Thon, Saumon, Anguille, Crevette crue, St. Jaques, Hokki, Maquereau, Oeuf de saumon | F14: Tuna, Salmon, Eel, Raw Shrimp, Scallop, Surf Clam (Hokkigai), Mackerel, Salmon Roe | G14: https://umjqopsyrylnvwkranvw.supabase.co/storage/v1/object/public/menu_img/sashimisp.webp | H14: FALSE | I14: Menu de midi | J14: 12
B15: BATTERA | C15: Battera (Pressed Mackerel Sushi) | D15: 18 | E15: (Sushi pressé de maquereau mariné ) | F15: (Pressed sushi with marinated mackerel) | G15: https://umjqopsyrylnvwkranvw.supabase.co/storage/v1/object/public/menu_img/battera.webp | H15: FALSE | I15: Menu de midi | J15: 13
B16: SAUMON SAUMON | C16: Salmon Salmon | D16: 22 | E16: (2 Sushi saumon+2 Sushi saumon mi-cuit+3 Makis saumon, 3 Makis saumon/avocat +8 tranches de saumon cru et oeuf de saumon) | F16: (2 salmon sushi + 2 lightly seared salmon sushi + 3 salmon maki rolls + 3 salmon & avocado maki rolls + 8 slices of raw salmon with salmon roe) | G16: https://umjqopsyrylnvwkranvw.supabase.co/storage/v1/object/public/menu_img/soso.webp | H16: FALSE | I16: Menu de midi | J16: 14
B17: POULET Teriyaki | C17: Chicken Teriyaki | D17: 18 | E17: (poulet grillé avec sauce caramélisée) | F17: (Grilled chicken with caramelized sauce) | G17: https://umjqopsyrylnvwkranvw.supabase.co/storage/v1/object/public/menu_img/teriyaki.webp | H17: FALSE | I17: Menu de midi | J17: 15
B18: POULET Yuzu-kosho | C18: Chicken Yuzu Kosho | D18: 18 | E18: (poulet grillé avec sauce caramélisée-pimentée au Yuzu) | F18: (Grilled chicken with caramelized yuzu chili sauce) | G18: https://umjqopsyrylnvwkranvw.supabase.co/storage/v1/object/public/menu_img/yuzukosho.webp | H18: FALSE | I18: Menu de midi | J18: 16
B19: SAUMON Grillé | C19: Grilled Salmon | D19: 18 | G19: https://umjqopsyrylnvwkranvw.supabase.co/storage/v1/object/public/menu_img/saumong.webp | H19: FALSE | I19: Menu de midi | J19: 17
B20: ANGUILLE Grillée | C20: Grilled Eel | D20: 22 | G20: https://umjqopsyrylnvwkranvw.supabase.co/storage/v1/object/public/menu_img/anguilleg.webp | H20: FALSE | I20: Menu de midi | J20: 18
B21: 【SOIR】SUSHI | C21: 【Dinner】Sushi | D21: 20 | E21: (8 sushis + 6 makis) Thon, Saumon, Poisson blanc, Maquereau, Seiche, Crevette cuite | F21: (8 sushi + 6 maki rolls) Tuna, Salmon, White Fish, Mackerel, Cuttlefish, Cooked Shrimp | H21: FALSE | I21: Menu de soir | J21: 19
B22: 【SOIR】SUSHI Spécial | C22: 【Dinner】Sushi Special | D22: 22 | E22: (9 sushis + 3 makis + 3 makis saumon-avocat) Thon, Saumon, Anguille, Crevette crue, St. Jaques, Hokki, Oeuf de saumon | F22: (9 sushi + 3 maki rolls + 3 salmon & avocado maki rolls) Tuna, Salmon, Eel, Raw Shrimp, Scallop, Surf Clam (Hokkigai), Salmon Roe | H22: FALSE | I22: Menu de soir | J22: 20
B23: 【SOIR】SUSHI Saumon | C23: 【Dinner】Sushi Salmon | D23: 20 | E23: (8 sushis Saumon cru et mi-cuit + 6 makis saumon) | F23: (8 sushi: raw and lightly seared salmon + 6 salmon maki rolls) | H23: FALSE | I23: Menu de soir | J23: 21
B24: 【SOIR】MAKI | C24: 【Dinner】Maki Rolls | D24: 20 | E24: (18 makis Thon, saumon, Saumon-avocat Concombre, Poisson blanc) | F24: (18 maki rolls) Tuna, Salmon, Salmon & Avocado, Cucumber, White Fish | H24: FALSE | I24: Menu de soir | J24: 22
B25: 【SOIR】CHIRASHI | C25: 【Dinner】Chirashi | D25: 20 | E25: Thon, Saumon, Poisson blanc, Maquereau, Seiche, Crevette cuite | F25: Tuna, Salmon, White Fish, Mackerel, Cuttlefish, Cooked Shrimp | H25: FALSE | I25: Menu de soir | J25: 23
B26: 【SOIR】CHIRASHI Spécial | C26: 【Dinner】Chirashi Special | D26: 23 | E26: Thon, Saumon, Anguille, Crevette crue, St. Jaques, Hokki, Maquereau, Oeuf de saumon | F26: Tuna, Salmon, Eel, Raw Shrimp, Scallop, Surf Clam (Hokkigai), Mackerel, Salmon Roe | H26: FALSE | I26: Menu de soir | J26: 24
B27: 【SOIR】CHIRASHI Saumon | C27: 【Dinner】Chirashi Salmon | D27: 20 | H27: FALSE | I27: Menu de soir | J27: 25
B28: 【SOIR】CHIRASHI Saumon Avocat | C28: 【Dinner】Chirashi Salmon & Avocado | D28: 22 | H28: FALSE | I28: Menu de soir | J28: 26
B29: 【SOIR】BARA CHIRASHI sauce maison | C29: 【Dinner】Bara Chirashi (House Special Sauce) | D29: 19 | E29: (Dés de poisson crus à la sauce sucrée sur grand bol de riz) | F29: (Diced raw fish with sweet sauce over a large bowl of rice) | H29: FALSE | I29: Menu de soir | J29: 27
B30: 【SOIR】Tartare de SAUMON | C30: 【Dinner】Salmon Tartare | D30: 19 | E30: (Saumon haché avec sauce blanche sur grand bol de riz) | F30: (Minced salmon with creamy white sauce over a large bowl of rice) | H30: FALSE | I30: Menu de soir | J30: 28
B31: 【SOIR】SASHIMI | C31: 【Dinner】Sashimi | D31: 20 | E31: Thon, Saumon, Poisson blanc, Maquereau, Séiche, Crevette cuite | F31: Tuna, Salmon, White Fish, Mackerel, Cuttlefish, Cooked Shrimp | H31: FALSE | I31: Menu de soir | J31: 29
B32: 【SOIR】SASHIMI Spécial | C32: 【Dinner】Sashimi Special | D32: 23 | E32: Thon, Saumon, Anguille, Crevette crue, St. Jaques, Hokki, Maquereau, Oeuf de saumon | F32: Tuna, Salmon, Eel, Raw Shrimp, Scallop, Surf Clam (Hokkigai), Mackerel, Salmon Roe | H32: FALSE | I32: Menu de soir | J32: 30
B33: 【SOIR】BATTERA | C33: 【Dinner】Battera (Pressed Mackerel Sushi) | D33: 19 | E33: (Sushi pressé de maquereau mariné ) | F33: (Pressed sushi with marinated mackerel) | H33: FALSE | I33: Menu de soir | J33: 31
B34: 【SOIR】SAUMON SAUMON | C34: 【Dinner】Salmon Salmon | D34: 23 | E34: (2 Sushi saumon+2 Sushi saumon mi-cuit+3 Makis saumon, 3 Makis saumon/avocat +8 tranches de saumon cru et oeuf de saumon) | F34: (2 salmon sushi + 2 lightly seared salmon sushi + 3 salmon maki rolls + 3 salmon & avocado maki rolls + 8 slices of raw salmon with salmon roe) | H34: FALSE | I34: Menu de soir | J34: 32
B35: 【SOIR】POULET Teriyaki | C35: 【Dinner】Chicken Teriyaki | D35: 19 | E35: (poulet grillé avec sauce caramélisée) | F35: (Grilled chicken with caramelized sauce) | H35: FALSE | I35: Menu de soir | J35: 33
B36: 【SOIR】POULET Yuzu-kosho | C36: 【Dinner】Chicken Yuzu Kosho | D36: 19 | E36: (poulet grillé avec sauce caramélisée-pimentée au Yuzu) | F36: (Grilled chicken with caramelized yuzu chili sauce) | H36: FALSE | I36: Menu de soir | J36: 34
B37: 【SOIR】SAUMON Grillé | C37: 【Dinner】Grilled Salmon | D37: 19 | H37: FALSE | I37: Menu de soir | J37: 35
B38: 【SOIR】ANGUILLE Grillée | C38: 【Dinner】Grilled Eel | D38: 23 | H38: FALSE | I38: Menu de soir | J38: 36
B39: Concombre | C39: Cucumber | D39: 5 | G39: https://umjqopsyrylnvwkranvw.supabase.co/storage/v1/object/public/menu_img/bara.webp | H39: FALSE | I39: À la carte | J39: 37
B40: Avocat | C40: Avocado | D40: 7 | G40: https://umjqopsyrylnvwkranvw.supabase.co/storage/v1/object/public/menu_img/bara.webp | H40: FALSE | I40: À la carte | J40: 38
...

Sheet CSV出力用
A1: このシートのA〜I列をコピー → テキストエディタに貼り付け → .csv保存 → Supabase の「Import data」でアップロード
A2: id | B2: name_fr | C2: name_en | D2: description_fr | E2: description_en | F2: price | G2: image_url | H2: featured | I2: category | J2: sort_order
A3: =menus!A3 -> 0 | B3: =menus!B3 -> SUSHI | C3: =menus!C3 -> Sushi | D3: =menus!E3 -> (8 sushis + 6 makis) Thon, Saumon, Poisson blanc, Maquereau, Seiche, Crevette cuite | E3: =menus!F3 -> (8 sushi + 6 maki rolls) Tuna, Salmon, White Fish, Mackerel, Cuttlefish, Cooked Shrimp | F3: =menus!D3 -> 19 | G3: =menus!G3 -> https://umjqopsyrylnvwkranvw.supabase.co/storage/v1/object/public/menu_img/sushi.webp | H3: =menus!H3 -> FALSE | I3: =menus!I3 -> Menu de midi | J3: =menus!J3 -> 1
A4: =menus!A4 -> 0 | B4: =menus!B4 -> SUSHI Spécial | C4: =menus!C4 -> Sushi Special | D4: =menus!E4 -> (9 sushis + 3 makis + 3 makis saumon-avocat) Thon, Saumon, Anguille, Crevette crue, St. Jaques, Hokki, Oeuf de saumon | E4: =menus!F4 -> (9 sushi + 3 maki rolls + 3 salmon & avocado maki rolls) Tuna, Salmon, Eel, Raw Shrimp, Scallop, Surf Clam (Hokkigai), Salmon Roe | F4: =menus!D4 -> 21 | G4: =menus!G4 -> https://umjqopsyrylnvwkranvw.supabase.co/storage/v1/object/public/menu_img/sushispecial.webp | H4: =menus!H4 -> FALSE | I4: =menus!I4 -> Menu de midi | J4: =menus!J4 -> 2
A5: =menus!A5 -> 0 | B5: =menus!B5 -> SUSHI Saumon | C5: =menus!C5 -> Sushi Salmon | D5: =menus!E5 -> (8 sushis Saumon cru et mi-cuit + 6 makis saumon) | E5: =menus!F5 -> (8 sushi: raw and lightly seared salmon + 6 salmon maki rolls) | F5: =menus!D5 -> 19 | G5: =menus!G5 -> https://umjqopsyrylnvwkranvw.supabase.co/storage/v1/object/public/menu_img/sushisaumon.webp | H5: =menus!H5 -> FALSE | I5: =menus!I5 -> Menu de midi | J5: =menus!J5 -> 3
A6: =menus!A6 -> 0 | B6: =menus!B6 -> MAKI | C6: =menus!C6 -> Maki Rolls | D6: =menus!E6 -> (18 makis Thon, saumon, Saumon-avocat Concombre, Poisson blanc) | E6: =menus!F6 -> (18 maki rolls) Tuna, Salmon, Salmon & Avocado, Cucumber, White Fish | F6: =menus!D6 -> 19 | G6: =menus!G6 -> https://umjqopsyrylnvwkranvw.supabase.co/storage/v1/object/public/menu_img/maki.webp | H6: =menus!H6 -> FALSE | I6: =menus!I6 -> Menu de midi | J6: =menus!J6 -> 4
A7: =menus!A7 -> 0 | B7: =menus!B7 -> CHIRASHI | C7: =menus!C7 -> Chirashi | D7: =menus!E7 -> Thon, Saumon, Poisson blanc, Maquereau, Seiche, Crevette cuite | E7: =menus!F7 -> Tuna, Salmon, White Fish, Mackerel, Cuttlefish, Cooked Shrimp | F7: =menus!D7 -> 19 | G7: =menus!G7 -> https://umjqopsyrylnvwkranvw.supabase.co/storage/v1/object/public/menu_img/chirashi.webp | H7: =menus!H7 -> FALSE | I7: =menus!I7 -> Menu de midi | J7: =menus!J7 -> 5
A8: =menus!A8 -> 0 | B8: =menus!B8 -> CHIRASHI Spécial | C8: =menus!C8 -> Chirashi Special | D8: =menus!E8 -> Thon, Saumon, Anguille, Crevette crue, St. Jaques, Hokki, Maquereau, Oeuf de saumon | E8: =menus!F8 -> Tuna, Salmon, Eel, Raw Shrimp, Scallop, Surf Clam (Hokkigai), Mackerel, Salmon Roe | F8: =menus!D8 -> 22 | G8: =menus!G8 -> https://umjqopsyrylnvwkranvw.supabase.co/storage/v1/object/public/menu_img/chirashisp.webp | H8: =menus!H8 -> FALSE | I8: =menus!I8 -> Menu de midi | J8: =menus!J8 -> 6
A9: =menus!A9 -> 0 | B9: =menus!B9 -> CHIRASHI Saumon | C9: =menus!C9 -> Chirashi Salmon | D9: =menus!E9 -> 0 | E9: =menus!F9 -> 0 | F9: =menus!D9 -> 19 | G9: =menus!G9 -> https://umjqopsyrylnvwkranvw.supabase.co/storage/v1/object/public/menu_img/chirashisaumon.webp | H9: =menus!H9 -> FALSE | I9: =menus!I9 -> Menu de midi | J9: =menus!J9 -> 7
A10: =menus!A10 -> 0 | B10: =menus!B10 -> CHIRASHI Saumon Avocat | C10: =menus!C10 -> Chirashi Salmon & Avocado | D10: =menus!E10 -> 0 | E10: =menus!F10 -> 0 | F10: =menus!D10 -> 20 | G10: =menus!G10 -> https://umjqopsyrylnvwkranvw.supabase.co/storage/v1/object/public/menu_img/chirashisa.webp | H10: =menus!H10 -> FALSE | I10: =menus!I10 -> Menu de midi | J10: =menus!J10 -> 8
A11: =menus!A11 -> 0 | B11: =menus!B11 -> BARA CHIRASHI sauce maison | C11: =menus!C11 -> Bara Chirashi (House Special Sauce) | D11: =menus!E11 -> (Dés de poisson crus à la sauce sucrée sur grand bol de riz) | E11: =menus!F11 -> (Diced raw fish with sweet sauce over a large bowl of rice) | F11: =menus!D11 -> 18 | G11: =menus!G11 -> https://umjqopsyrylnvwkranvw.supabase.co/storage/v1/object/public/menu_img/bara.webp | H11: =menus!H11 -> FALSE | I11: =menus!I11 -> Menu de midi | J11: =menus!J11 -> 9
A12: =menus!A12 -> 0 | B12: =menus!B12 -> Tartare de SAUMON | C12: =menus!C12 -> Salmon Tartare | D12: =menus!E12 -> (Saumon haché avec sauce blanche sur grand bol de riz) | E12: =menus!F12 -> (Minced salmon with creamy white sauce over a large bowl of rice) | F12: =menus!D12 -> 18 | G12: =menus!G12 -> https://umjqopsyrylnvwkranvw.supabase.co/storage/v1/object/public/menu_img/bara.webp | H12: =menus!H12 -> FALSE | I12: =menus!I12 -> Menu de midi | J12: =menus!J12 -> 10
A13: =menus!A13 -> 0 | B13: =menus!B13 -> SASHIMI | C13: =menus!C13 -> Sashimi | D13: =menus!E13 -> Thon, Saumon, Poisson blanc, Maquereau, Séiche, Crevette cuite | E13: =menus!F13 -> Tuna, Salmon, White Fish, Mackerel, Cuttlefish, Cooked Shrimp | F13: =menus!D13 -> 19 | G13: =menus!G13 -> https://umjqopsyrylnvwkranvw.supabase.co/storage/v1/object/public/menu_img/sashimi.webp | H13: =menus!H13 -> FALSE | I13: =menus!I13 -> Menu de midi | J13: =menus!J13 -> 11
A14: =menus!A14 -> 0 | B14: =menus!B14 -> SASHIMI Spécial | C14: =menus!C14 -> Sashimi Special | D14: =menus!E14 -> Thon, Saumon, Anguille, Crevette crue, St. Jaques, Hokki, Maquereau, Oeuf de saumon | E14: =menus!F14 -> Tuna, Salmon, Eel, Raw Shrimp, Scallop, Surf Clam (Hokkigai), Mackerel, Salmon Roe | F14: =menus!D14 -> 22 | G14: =menus!G14 -> https://umjqopsyrylnvwkranvw.supabase.co/storage/v1/object/public/menu_img/sashimisp.webp | H14: =menus!H14 -> FALSE | I14: =menus!I14 -> Menu de midi | J14: =menus!J14 -> 12
... A20: =menus!A20 -> 0 | B20: =menus!B20 -> ANGUILLE Grillée | C20: =menus!C20 -> Grilled Eel | D20: =menus!E20 -> 0 | E20: =menus!F20 -> 0 | F20: =menus!D20 -> 22 | G20: =menus!G20 -> https://umjqopsyrylnvwkranvw.supabase.co/storage/v1/object/public/menu_img/anguilleg.webp | H20: =menus!H20 -> FALSE | I20: =menus!I20 -> Menu de midi | J20: =menus!J20 -> 18
A21: =menus!A21 -> 0 | B21: =menus!B21 -> 【SOIR】SUSHI | C21: =menus!C21 -> 【Dinner】Sushi | D21: =menus!E21 -> (8 sushis + 6 makis) Thon, Saumon, Poisson blanc, Maquereau, Seiche, Crevette cuite | E21: =menus!F21 -> (8 sushi + 6 maki rolls) Tuna, Salmon, White Fish, Mackerel, Cuttlefish, Cooked Shrimp | F21: =menus!D21 -> 20 | G21: =menus!G3 -> https://umjqopsyrylnvwkranvw.supabase.co/storage/v1/object/public/menu_img/sushi.webp | H21: =menus!H21 -> FALSE | I21: =menus!I21 -> Menu de soir | J21: =menus!J21 -> 19
A22: =menus!A22 -> 0 | B22: =menus!B22 -> 【SOIR】SUSHI Spécial | C22: =menus!C22 -> 【Dinner】Sushi Special | D22: =menus!E22 -> (9 sushis + 3 makis + 3 makis saumon-avocat) Thon, Saumon, Anguille, Crevette crue, St. Jaques, Hokki, Oeuf de saumon | E22: =menus!F22 -> (9 sushi + 3 maki rolls + 3 salmon & avocado maki rolls) Tuna, Salmon, Eel, Raw Shrimp, Scallop, Surf Clam (Hokkigai), Salmon Roe | F22: =menus!D22 -> 22 | G22: =menus!G4 -> https://umjqopsyrylnvwkranvw.supabase.co/storage/v1/object/public/menu_img/sushispecial.webp | H22: =menus!H22 -> FALSE | I22: =menus!I22 -> Menu de soir | J22: =menus!J22 -> 20
A23: =menus!A23 -> 0 | B23: =menus!B23 -> 【SOIR】SUSHI Saumon | C23: =menus!C23 -> 【Dinner】Sushi Salmon | D23: =menus!E23 -> (8 sushis Saumon cru et mi-cuit + 6 makis saumon) | E23: =menus!F23 -> (8 sushi: raw and lightly seared salmon + 6 salmon maki rolls) | F23: =menus!D23 -> 20 | G23: =menus!G5 -> https://umjqopsyrylnvwkranvw.supabase.co/storage/v1/object/public/menu_img/sushisaumon.webp | H23: =menus!H23 -> FALSE | I23: =menus!I23 -> Menu de soir | J23: =menus!J23 -> 21
A24: =menus!A24 -> 0 | B24: =menus!B24 -> 【SOIR】MAKI | C24: =menus!C24 -> 【Dinner】Maki Rolls | D24: =menus!E24 -> (18 makis Thon, saumon, Saumon-avocat Concombre, Poisson blanc) | E24: =menus!F24 -> (18 maki rolls) Tuna, Salmon, Salmon & Avocado, Cucumber, White Fish | F24: =menus!D24 -> 20 | G24: =menus!G6 -> https://umjqopsyrylnvwkranvw.supabase.co/storage/v1/object/public/menu_img/maki.webp | H24: =menus!H24 -> FALSE | I24: =menus!I24 -> Menu de soir | J24: =menus!J24 -> 22
A25: =menus!A25 -> 0 | B25: =menus!B25 -> 【SOIR】CHIRASHI | C25: =menus!C25 -> 【Dinner】Chirashi | D25: =menus!E25 -> Thon, Saumon, Poisson blanc, Maquereau, Seiche, Crevette cuite | E25: =menus!F25 -> Tuna, Salmon, White Fish, Mackerel, Cuttlefish, Cooked Shrimp | F25: =menus!D25 -> 20 | G25: =menus!G7 -> https://umjqopsyrylnvwkranvw.supabase.co/storage/v1/object/public/menu_img/chirashi.webp | H25: =menus!H25 -> FALSE | I25: =menus!I25 -> Menu de soir | J25: =menus!J25 -> 23
A26: =menus!A26 -> 0 | B26: =menus!B26 -> 【SOIR】CHIRASHI Spécial | C26: =menus!C26 -> 【Dinner】Chirashi Special | D26: =menus!E26 -> Thon, Saumon, Anguille, Crevette crue, St. Jaques, Hokki, Maquereau, Oeuf de saumon | E26: =menus!F26 -> Tuna, Salmon, Eel, Raw Shrimp, Scallop, Surf Clam (Hokkigai), Mackerel, Salmon Roe | F26: =menus!D26 -> 23 | G26: =menus!G8 -> https://umjqopsyrylnvwkranvw.supabase.co/storage/v1/object/public/menu_img/chirashisp.webp | H26: =menus!H26 -> FALSE | I26: =menus!I26 -> Menu de soir | J26: =menus!J26 -> 24
A27: =menus!A27 -> 0 | B27: =menus!B27 -> 【SOIR】CHIRASHI Saumon | C27: =menus!C27 -> 【Dinner】Chirashi Salmon | D27: =menus!E27 -> 0 | E27: =menus!F27 -> 0 | F27: =menus!D27 -> 20 | G27: =menus!G9 -> https://umjqopsyrylnvwkranvw.supabase.co/storage/v1/object/public/menu_img/chirashisaumon.webp | H27: =menus!H27 -> FALSE | I27: =menus!I27 -> Menu de soir | J27: =menus!J27 -> 25
A28: =menus!A28 -> 0 | B28: =menus!B28 -> 【SOIR】CHIRASHI Saumon Avocat | C28: =menus!C28 -> 【Dinner】Chirashi Salmon & Avocado | D28: =menus!E28 -> 0 | E28: =menus!F28 -> 0 | F28: =menus!D28 -> 22 | G28: =menus!G10 -> https://umjqopsyrylnvwkranvw.supabase.co/storage/v1/object/public/menu_img/chirashisa.webp | H28: =menus!H28 -> FALSE | I28: =menus!I28 -> Menu de soir | J28: =menus!J28 -> 26
A29: =menus!A29 -> 0 | B29: =menus!B29 -> 【SOIR】BARA CHIRASHI sauce maison | C29: =menus!C29 -> 【Dinner】Bara Chirashi (House Special Sauce) | D29: =menus!E29 -> (Dés de poisson crus à la sauce sucrée sur grand bol de riz) | E29: =menus!F29 -> (Diced raw fish with sweet sauce over a large bowl of rice) | F29: =menus!D29 -> 19 | G29: =menus!G11 -> https://umjqopsyrylnvwkranvw.supabase.co/storage/v1/object/public/menu_img/bara.webp | H29: =menus!H29 -> FALSE | I29: =menus!I29 -> Menu de soir | J29: =menus!J29 -> 27
A30: =menus!A30 -> 0 | B30: =menus!B30 -> 【SOIR】Tartare de SAUMON | C30: =menus!C30 -> 【Dinner】Salmon Tartare | D30: =menus!E30 -> (Saumon haché avec sauce blanche sur grand bol de riz) | E30: =menus!F30 -> (Minced salmon with creamy white sauce over a large bowl of rice) | F30: =menus!D30 -> 19 | G30: =menus!G12 -> https://umjqopsyrylnvwkranvw.supabase.co/storage/v1/object/public/menu_img/bara.webp | H30: =menus!H30 -> FALSE | I30: =menus!I30 -> Menu de soir | J30: =menus!J30 -> 28
A31: =menus!A31 -> 0 | B31: =menus!B31 -> 【SOIR】SASHIMI | C31: =menus!C31 -> 【Dinner】Sashimi | D31: =menus!E31 -> Thon, Saumon, Poisson blanc, Maquereau, Séiche, Crevette cuite | E31: =menus!F31 -> Tuna, Salmon, White Fish, Mackerel, Cuttlefish, Cooked Shrimp | F31: =menus!D31 -> 20 | G31: =menus!G13 -> https://umjqopsyrylnvwkranvw.supabase.co/storage/v1/object/public/menu_img/sashimi.webp | H31: =menus!H31 -> FALSE | I31: =menus!I31 -> Menu de soir | J31: =menus!J31 -> 29
A32: =menus!A32 -> 0 | B32: =menus!B32 -> 【SOIR】SASHIMI Spécial | C32: =menus!C32 -> 【Dinner】Sashimi Special | D32: =menus!E32 -> Thon, Saumon, Anguille, Crevette crue, St. Jaques, Hokki, Maquereau, Oeuf de saumon | E32: =menus!F32 -> Tuna, Salmon, Eel, Raw Shrimp, Scallop, Surf Clam (Hokkigai), Mackerel, Salmon Roe | F32: =menus!D32 -> 23 | G32: =menus!G14 -> https://umjqopsyrylnvwkranvw.supabase.co/storage/v1/object/public/menu_img/sashimisp.webp | H32: =menus!H32 -> FALSE | I32: =menus!I32 -> Menu de soir | J32: =menus!J32 -> 30
... A38: =menus!A38 -> 0 | B38: =menus!B38 -> 【SOIR】ANGUILLE Grillée | C38: =menus!C38 -> 【Dinner】Grilled Eel | D38: =menus!E38 -> 0 | E38: =menus!F38 -> 0 | F38: =menus!D38 -> 23 | G38: =menus!G20 -> https://umjqopsyrylnvwkranvw.supabase.co/storage/v1/object/public/menu_img/anguilleg.webp | H38: =menus!H38 -> FALSE | I38: =menus!I38 -> Menu de soir | J38: =menus!J38 -> 36
A39: =menus!A39 -> 0 | B39: =menus!B39 -> Concombre | C39: =menus!C39 -> Cucumber | D39: =menus!E39 -> 0 | E39: =menus!F39 -> 0 | F39: =menus!D39 -> 5 | G39: =menus!G39 -> https://umjqopsyrylnvwkranvw.supabase.co/storage/v1/object/public/menu_img/bara.webp | H39: =menus!H39 -> FALSE | I39: =menus!I39 -> À la carte | J39: =menus!J39 -> 37
A40: =menus!A40 -> 0 | B40: =menus!B40 -> Avocat | C40: =menus!C40 -> Avocado | D40: =menus!E40 -> 0 | E40: =menus!F40 -> 0 | F40: =menus!D40 -> 7 | G40: =menus!G40 -> https://umjqopsyrylnvwkranvw.supabase.co/storage/v1/object/public/menu_img/bara.webp | H40: =menus!H40 -> FALSE | I40: =menus!I40 -> À la carte | J40: =menus!J40 -> 38
A41: =menus!A41 -> 0 | B41: =menus!B41 -> Thon | C41: =menus!C41 -> Tuna | D41: =menus!E41 -> 0 | E41: =menus!F41 -> 0 | F41: =menus!D41 -> 8 | G41: =menus!G41 -> https://umjqopsyrylnvwkranvw.supabase.co/storage/v1/object/public/menu_img/bara.webp | H41: =menus!H41 -> FALSE | I41: =menus!I41 -> À la carte | J41: =menus!J41 -> 39
A42: =menus!A42 -> 0 | B42: =menus!B42 -> Saumon | C42: =menus!C42 -> Salmon | D42: =menus!E42 -> 0 | E42: =menus!F42 -> 0 | F42: =menus!D42 -> 7 | G42: =menus!G42 -> https://umjqopsyrylnvwkranvw.supabase.co/storage/v1/object/public/menu_img/bara.webp | H42: =menus!H42 -> FALSE | I42: =menus!I42 -> À la carte | J42: =menus!J42 -> 40
A43: =menus!A43 -> 0 | B43: =menus!B43 -> Tartare saumon | C43: =menus!C43 -> Salmon Tartare | D43: =menus!E43 -> 0 | E43: =menus!F43 -> 0 | F43: =menus!D43 -> 7 | G43: =menus!G43 -> https://umjqopsyrylnvwkranvw.supabase.co/storage/v1/object/public/menu_img/bara.webp | H43: =menus!H43 -> FALSE | I43: =menus!I43 -> À la carte | J43: =menus!J43 -> 41
A44: =menus!A44 -> 0 | B44: =menus!B44 -> Saumon-avocat | C44: =menus!C44 -> Salmon & Avocado | D44: =menus!E44 -> 0 | E44: =menus!F44 -> 0 | F44: =menus!D44 -> 8 | G44: =menus!G44 -> https://umjqopsyrylnvwkranvw.supabase.co/storage/v1/object/public/menu_img/bara.webp | H44: =menus!H44 -> FALSE | I44: =menus!I44 -> À la carte | J44: =menus!J44 -> 42
A45: =menus!A45 -> 0 | B45: =menus!B45 -> Crevette-avocat | C45: =menus!C45 -> Shrimp & Avocado | D45: =menus!E45 -> 0 | E45: =menus!F45 -> 0 | F45: =menus!D45 -> 8 | G45: =menus!G45 -> https://umjqopsyrylnvwkranvw.supabase.co/storage/v1/object/public/menu_img/bara.webp | H45: =menus!H45 -> FALSE | I45: =menus!I45 -> À la carte | J45: =menus!J45 -> 43
A46: =menus!A46 -> 0 | B46: =menus!B46 -> Anguille | C46: =menus!C46 -> Eel | D46: =menus!E46 -> 0 | E46: =menus!F46 -> 0 | F46: =menus!D46 -> 8 | G46: =menus!G46 -> https://umjqopsyrylnvwkranvw.supabase.co/storage/v1/object/public/menu_img/bara.webp | H46: =menus!H46 -> FALSE | I46: =menus!I46 -> À la carte | J46: =menus!J46 -> 44
A47: =menus!A47 -> 0 | B47: =menus!B47 -> Futomaki | C47: =menus!C47 -> Futomaki Roll | D47: =menus!E47 -> 0 | E47: =menus!F47 -> 0 | F47: =menus!D47 -> 18 | G47: =menus!G47 -> https://umjqopsyrylnvwkranvw.supabase.co/storage/v1/object/public/menu_img/bara.webp | H47: =menus!H47 -> FALSE | I47: =menus!I47 -> À la carte | J47: =menus!J47 -> 45
A48: =menus!A48 -> 0 | B48: =menus!B48 -> Futomaki végétarien | C48: =menus!C48 -> Vegetarian Futomaki Roll | D48: =menus!E48 -> 0 | E48: =menus!F48 -> 0 | F48: =menus!D48 -> 16 | G48: =menus!G48 -> https://umjqopsyrylnvwkranvw.supabase.co/storage/v1/object/public/menu_img/bara.webp | H48: =menus!H48 -> FALSE | I48: =menus!I48 -> À la carte | J48: =menus!J48 -> 46
A49: =menus!A49 -> 0 | B49: =menus!B49 -> Anguille, Crevette crue, Coquille St.Jaques, Seiche, Omelette | C49: =menus!C49 -> Eel, Raw Shrimp, Scallop, Cuttlefish, Omelet | D49: =menus!E49 -> 0 | E49: =menus!F49 -> 0 | F49: =menus!D49 -> 5 | G49: =menus!G49 -> https://umjqopsyrylnvwkranvw.supabase.co/storage/v1/object/public/menu_img/bara.webp | H49: =menus!H49 -> FALSE | I49: =menus!I49 -> À la carte | J49: =menus!J49 -> 47
A50: =menus!A50 -> 0 | B50: =menus!B50 -> Bar, Daurade, Crevette cuite | C50: =menus!C50 -> Sea Bass, Sea Bream, Cooked Shrimp | D50: =menus!E50 -> 0 | E50: =menus!F50 -> 0 | F50: =menus!D50 -> 6 | G50: =menus!G50 -> https://umjqopsyrylnvwkranvw.supabase.co/storage/v1/object/public/menu_img/bara.webp | H50: =menus!H50 -> FALSE | I50: =menus!I50 -> À la carte | J50: =menus!J50 -> 48
...

Sheet Sheet3
A1: French | B1: 【Dinner】 | C1: English | D1: 【Dinner】English
A2: SUSHI | B2: 【Dinner】 | C2: Sushi | D2: 【Dinner】Sushi
A3: SUSHI Spécial | B3: 【Dinner】 | C3: Sushi Special | D3: 【Dinner】Sushi Special
A4: SUSHI Saumon | B4: 【Dinner】 | C4: Sushi Salmon | D4: 【Dinner】Sushi Salmon
A5: MAKI | B5: 【Dinner】 | C5: Maki Rolls | D5: 【Dinner】Maki Rolls
A6: CHIRASHI | B6: 【Dinner】 | C6: Chirashi | D6: 【Dinner】Chirashi
A7: CHIRASHI Spécial | B7: 【Dinner】 | C7: Chirashi Special | D7: 【Dinner】Chirashi Special
A8: CHIRASHI Saumon | B8: 【Dinner】 | C8: Chirashi Salmon | D8: 【Dinner】Chirashi Salmon
A9: CHIRASHI Saumon Avocat | B9: 【Dinner】 | C9: Chirashi Salmon & Avocado | D9: 【Dinner】Chirashi Salmon & Avocado
A10: BARA CHIRASHI sauce maison | B10: 【Dinner】 | C10: Bara Chirashi (House Special Sauce) | D10: 【Dinner】Bara Chirashi (House Special Sauce)
A11: Tartare de SAUMON | B11: 【Dinner】 | C11: Salmon Tartare | D11: 【Dinner】Salmon Tartare
A12: SASHIMI | B12: 【Dinner】 | C12: Sashimi | D12: 【Dinner】Sashimi
... A19: ANGUILLE Grillée | B19: 【Dinner】 | C19: Grilled Eel | D19: 【Dinner】Grilled Eel
A20: 【SOIR】SUSHI
A21: 【SOIR】SUSHI Spécial
A22: 【SOIR】SUSHI Saumon
A23: 【SOIR】MAKI
A24: 【SOIR】CHIRASHI
A25: 【SOIR】CHIRASHI Spécial
A26: 【SOIR】CHIRASHI Saumon
A27: 【SOIR】CHIRASHI Saumon Avocat
A28: 【SOIR】BARA CHIRASHI sauce maison
A29: 【SOIR】Tartare de SAUMON
A30: 【SOIR】SASHIMI
A31: 【SOIR】SASHIMI Spécial
... A37: 【SOIR】ANGUILLE Grillée
A38: Concombre | C38: Cucumber
A39: Avocat | C39: Avocado
A40: Thon | C40: Tuna
A41: Saumon | C41: Salmon
A42: Tartare saumon | C42: Salmon Tartare
A43: Saumon-avocat | C43: Salmon & Avocado
A44: Crevette-avocat | C44: Shrimp & Avocado
A45: Anguille | C45: Eel
A46: Futomaki | C46: Futomaki Roll
A47: Futomaki végétarien | C47: Vegetarian Futomaki Roll
A48: Anguille, Crevette crue, Coquille St.Jaques, Seiche, Omelette | C48: Eel, Raw Shrimp, Scallop, Cuttlefish, Japanese Omelet
A49: Bar, Daurade, Crevette cuite | C49: Sea Bass, Sea Bream, Cooked Shrimp
... A58: Bière Japonaise (KIRIN ou ASAHI) | C58: Japanese Beer (Kirin or Asahi)

Sheet カテゴリ凡例
A1: カテゴリ名 | B1: 説明 | C1: index.htmlフィルター
A2: Menu de midi | B2: ランチメニュー（昼のセット） | C2: Menu de midi
A3: Menu de soir | B3: ディナーメニュー（夜のセット） | C3: Menu de soir
A4: À la carte | B4: アラカルト（単品） | C4: À la carte
A5: Boissons | B5: ドリンク類 | C5: Boissons
A7: ⚠️ category カラムの値はindex.htmlのフィルターボタンと完全一致が必要です（大文字・小文字・スペースに注意）
